Workbook

Sheet 2. Reglas de Calidad (2)
A1: Integración de la info de inversión a través de Google Sheet | B1: ID Regla de calidad | C1: Nombre del Entidad de Dato | D1: Descripción de Regla de calidad | E1: Priorizada | F1: Motivo | G1: Tipo de regla de calidad | H1: Principio de calidad asociado | I1: Umbral Superior | J1: Umbral Inferior | K1: Periodicidad | L1: Fecha de creación | M1: Validado por Data Owner | N1: Código de Entidad del Dato
A2: Caso de uso que corresponde | B2: Identificador de Regla de Calidad | C2: Nombre único con el cual el Negocio identifica al Entidad de Dato | D2: Descripción detallada de la regla de calidad que se quiere aplicar sobre el dato | G2: Indica si se trata de una regla básica o una regla experta | H2: Se debe indicar el principio de calidad al que se hace referencia (Consistencia, completitud, etc) | I2: Indica el límite superior sobre los valores que puede tomar el dato | J2: Indica el límite inferior sobre los valores que puede tomar el dato | K2: Frecuencia con la que se aplica | L2: Indica la fecha de creación | M2: Una vez revisado por el Data Owner se coloca Sí en señal de conformidad con la definición | N2: Código de Entidad del Dato
A3: Gente Imparable | B3: =+UPPER(MID(A3,1,3))&"00"&COUNTA(A$3) -> GEN001 | C3: Índice de Engagement | D3: Se mide entre un rango del 1 al 7, no deben existir valores negativos: 1, 2,3 Negativo 4 Neutro 5,6,7 Positivo | E3: Priorizada | F3: Regla obligatoria | G3: Básica | H3: Validez | N3: -
A4: Gente Imparable | B4: =+UPPER(MID(A4,1,3))&"00"&COUNTA(A$3:A4) -> GEN002 | C4: Índice de Engagement | D4: Los valores se categorizan de la siguiente manera: Percepción Negativa Alta (1) Percepción Negativa Media (2) Percepción Negativa Baja (3) Percepción Neutro (4) Percepción Positiva Baja (5) Percepción Positiva Media (6) Percepción Positiva Alta (7) | E4: Priorizada | F4: Regla obligatoria | G4: Experta | H4: Consistencia | N4: -
A5: CRM | B5: =+UPPER(MID(A5,1,3))&"00"&COUNTA(A$3:A5) -> CRM003 | C5: Id Cliente | D5: No debe existir duplicados, son valores únicos. | E5: Priorizada | F5: Regla obligatoria | G5: Básica | H5: Integridad | I5: 1 | J5: 1 | K5: A demanda | L5: - | M5: No revisado | N5: CRM00001
A6: CRM | B6: =+UPPER(MID(A6,1,3))&"00"&COUNTA(A$3:A6) -> CRM004 | C6: Tipo de cliente | D6: Los valores aceptados son, de tipo númerico: Valor 1 : PERSONA NATURAL Valor 2: PERSONA JURIDICA | E6: Priorizada | F6: Regla obligatoria | G6: Básica | H6: Validez | I6: 1 | J6: 1 | K6: A demanda | M6: No revisado | N6: CRM00002
A7: CRM | B7: =+UPPER(MID(A7,1,3))&"00"&COUNTA(A$3:A7) -> CRM005 | C7: Razón social | D7: No deberia contener caracteres especiales, tampoco saltos de linea ni tabuladores, tampoco el caracter de palote (|), tener cuidado, ya que los valores aceptados pueden ser: &, -, ., ", / | E7: Priorizada | F7: Regla obligatoria | G7: Básica | H7: Validez | I7: 1 | J7: 1 | K7: A demanda | M7: No revisado | N7: CRM00003
A8: CRM | B8: =+UPPER(MID(A8,1,3))&"00"&COUNTA(A$3:A8) -> CRM006 | C8: Nombre | D8: Esta regla valida que los valores en el campo NOMBRE cumplan con los estándares adecuados, evitando caracteres no permitidos, nombres incorrectos o datos inválidos. Se consideran valores incorrectos aquellos que: Contienen caracteres especiales no permitidos, como |, !, ", /, :, $, &, ?, ¡, ¿, =, {, [, +, *, ~, ^, }, ], \, ;, °, #, (, ), ,, <, >, ¬, --, entre otros. Son nombres inválidos o placeholders, como --, NO REP, ,, ., :. Tienen menos de 2 caracteres, lo que indicaría un posible error en la captura. Empiezan con un número (0-9), lo cual no es válido para un nombre. No corresponden a nombres reales, excluyendo abreviaturas incorrectas (A, B, C... hasta Z) y sus versiones con punto (A., B., C....). | E8: Priorizada | F8: Regla obligatoria | G8: Básica | H8: Validez | I8: 1 | J8: 1 | K8: A demanda | M8: No revisado | N8: CRM00004
A9: CRM | B9: =+UPPER(MID(A9,1,3))&"00"&COUNTA(A$3:A9) -> CRM007 | C9: Apellido Paterno | D9: Esta regla valida que los valores en el campo APELLIDO_PATERNO cumplan con los estándares adecuados, evitando caracteres no permitidos, nombres incorrectos o datos inválidos. Se consideran valores incorrectos aquellos que: Contienen caracteres especiales no permitidos, como |, !, ", /, :, $, &, ?, ¡, ¿, =, {, [, +, *, ~, ^, }, ], \, ;, °, #, (, ), ,, <, >, ¬, --, entre otros. Son nombres inválidos o placeholders, como --, NO REP, ,, ., :. Tienen menos de 2 caracteres, lo que indicaría un posible error en la captura. Empiezan con un número (0-9), lo cual no es válido para un nombre. No corresponden a nombres reales, excluyendo abreviaturas incorrectas (A, B, C... hasta Z) y sus versiones con punto (A., B., C....). | E9: Priorizada | F9: Regla obligatoria | G9: Básica | H9: Validez | I9: 1 | J9: 1 | K9: A demanda | M9: No revisado | N9: CRM00005
A10: CRM | B10: =+UPPER(MID(A10,1,3))&"00"&COUNTA(A$3:A10) -> CRM008 | C10: Apellido Materno | D10: Esta regla valida que los valores en el campo APELLIDO_MATERNO cumplan con los estándares adecuados, evitando caracteres no permitidos, nombres incorrectos o datos inválidos. Se consideran valores incorrectos aquellos que: Contienen caracteres especiales no permitidos, como |, !, ", /, :, $, &, ?, ¡, ¿, =, {, [, +, *, ~, ^, }, ], \, ;, °, #, (, ), ,, <, >, ¬, --, entre otros. Son nombres inválidos o placeholders, como --, NO REP, ,, ., :. Tienen menos de 2 caracteres, lo que indicaría un posible error en la captura. Empiezan con un número (0-9), lo cual no es válido para un nombre. No corresponden a nombres reales, excluyendo abreviaturas incorrectas (A, B, C... hasta Z) y sus versiones con punto (A., B., C....). | E10: Priorizada | F10: Regla obligatoria | G10: Básica | H10: Validez | I10: 1 | J10: 1 | K10: A demanda | M10: No revisado | N10: CRM00006
A11: CRM | B11: =+UPPER(MID(A11,1,3))&"00"&COUNTA(A$3:A11) -> CRM009 | C11: Nombre de contacto de la empresa | D11: "Esta regla valida que los valores en el campo NOMBRE_CONTACTO_EMPRESA cumplan con los estándares adecuados, evitando caracteres no permitidos, nombres incorrectos o datos inválidos. Se consideran valores incorrectos aquellos que: Contienen caracteres especiales no permitidos, como |, !, "", /, :, $, &, ?, ¡, ¿, =, {, [, +, *, ~, ^, }, ], \, ;, °, #, (, ), ,, <, >, ¬, --, entre otros. Son nombres inválidos o placeholders, como --, NO REP, ,, ., :. Tienen menos de 2 caracteres, lo que indicaría un posible error en la captura. Empiezan con un número (0-9), lo cual no es válido para un nombre. No corresponden a nombres reales, excluyendo abreviaturas incorrectas (A, B, C... hasta Z) y sus versiones con punto (A., B., C....)." | E11: Priorizada | F11: Regla obligatoria | G11: Básica | H11: Validez | I11: 1 | J11: 1 | K11: A demanda | M11: No revisado | N11: CRM00007
A12: CRM | B12: =+UPPER(MID(A12,1,3))&"00"&COUNTA(A$3:A12) -> CRM0010 | C12: Apellido paterno de contacto de la empresa | D12: Esta regla valida que los valores en el campo APELLIDO_PATERNO_CONTACTO_EMPRESA cumplan con los estándares adecuados, evitando caracteres no permitidos, nombres incorrectos o datos inválidos. Se consideran valores incorrectos aquellos que: Contienen caracteres especiales no permitidos, como |, !, ", /, :, $, &, ?, ¡, ¿, =, {, [, +, *, ~, ^, }, ], \, ;, °, #, (, ), ,, <, >, ¬, --, entre otros. Son nombres inválidos o placeholders, como --, NO REP, ,, ., :. Tienen menos de 2 caracteres, lo que indicaría un posible error en la captura. Empiezan con un número (0-9), lo cual no es válido para un nombre. No corresponden a nombres reales, excluyendo abreviaturas incorrectas (A, B, C... hasta Z) y sus versiones con punto (A., B., C....). | E12: Priorizada | F12: Regla obligatoria | G12: Básica | H12: Validez | I12: 1 | J12: 1 | K12: A demanda | M12: No revisado | N12: CRM00008
A13: CRM | B13: =+UPPER(MID(A13,1,3))&"00"&COUNTA(A$3:A13) -> CRM0011 | C13: Apellido materno de contacto de la empresa | D13: Esta regla valida que los valores en el campo APELLIDO_MATERNO_CONTACTO_EMPRESA cumplan con los estándares adecuados, evitando caracteres no permitidos, nombres incorrectos o datos inválidos. Se consideran valores incorrectos aquellos que: Contienen caracteres especiales no permitidos, como |, !, ", /, :, $, &, ?, ¡, ¿, =, {, [, +, *, ~, ^, }, ], \, ;, °, #, (, ), ,, <, >, ¬, --, entre otros. Son nombres inválidos o placeholders, como --, NO REP, ,, ., :. Tienen menos de 2 caracteres, lo que indicaría un posible error en la captura. Empiezan con un número (0-9), lo cual no es válido para un nombre. No corresponden a nombres reales, excluyendo abreviaturas incorrectas (A, B, C... hasta Z) y sus versiones con punto (A., B., C....). | E13: Priorizada | F13: Regla obligatoria | G13: Básica | H13: Validez | I13: 1 | J13: 1 | K13: A demanda | M13: No revisado | N13: CRM00009
A14: CRM | B14: =+UPPER(MID(A14,1,3))&"00"&COUNTA(A$3:A14) -> CRM0012 | C14: Tipo Documento | D14: Puede ser 1 = PERSONA NATURAL, 2 = PERSONA JURIDICA, pero estos se pueden abrir por 1 DNI 1 CARNET DE EXTRANJERÍA 1 PASAPORTE 2 TIN 2 RUC PJ | E14: Priorizada | F14: Regla obligatoria | G14: Básica | H14: Validez | I14: 1 | J14: 1 | K14: A demanda | M14: No revisado | N14: CRM00010
A15: CRM | B15: =+UPPER(MID(A15,1,3))&"00"&COUNTA(A$3:A15) -> CRM0013 | C15: Número Documento | D15: El campo es de tipo texto, las longitudes maximas permitidas son: 1 DNI : 8, minima = 8, maxima = 8 1 CARNET DE EXTRANJERÍA 14, minima = 9, maxima = 14 1 PASAPORTE 13, minima = 9, maxima = 13 2 TIN: 14, minima = 9, maxima = 14 2 RUC PJ : 11, minima = 11, maxima = 11 | E15: Priorizada | F15: Regla obligatoria | G15: Básica | H15: Validez | I15: 1 | J15: 1 | K15: A demanda | M15: No revisado | N15: CRM00011
A16: CRM | B16: =+UPPER(MID(A16,1,3))&"00"&COUNTA(A$3:A16) -> CRM0014 | C16: RUC de persona natural | D16: El campo es de tipo texto, las longitudes maximas permitidas son: RUC : 11, minima = 11, maxima = 11 | E16: Priorizada | F16: Regla obligatoria | G16: Básica | H16: Validez | I16: 1 | J16: 1 | K16: A demanda | M16: No revisado | N16: CRM00012
A17: CRM | B17: =+UPPER(MID(A17,1,3))&"00"&COUNTA(A$3:A17) -> CRM0015 | C17: Grupo económico | D17: Valor de tipo texto, descripcion de grupo economico, maximo valor de caracteres: 100, minimo: 3 | E17: Priorizada | F17: Regla obligatoria | G17: Básica | H17: Validez | I17: 1 | J17: 1 | K17: A demanda | M17: No revisado | N17: CRM00013
... A34: CRM | B34: =+UPPER(MID(A34,1,3))&"00"&COUNTA(A$3:A34) -> CRM0032 | C34: Tipo de participante de póliza | D34: Regla tabla insis, Tipo de participante de poliza, dato de tipo texto, considerar una longitud maxima de 50 caracteres, para mayor detalle revisar tabla INSIS_PEOPLE_V10.HT_PEOPLE_ROLE, campo NAME | E34: Priorizada | F34: Regla obligatoria | G34: Básica | H34: Validez | I34: 1 | J34: 1 | K34: A demanda | M34: No revisado | N34: CRM00030

Sheet 0. Leyenda del Diccionario
B1: Tipo de Metadato | C1: Responsables
B2: Metadatos funcionales | C2: Data Owner | S2: Decisión | T2: Tipo de Dato | U2: Tipo | V2: Prioridad
B3: Control de cambios | C3: Data Officer | S3: SÍ | T3: Origen | U3: Indicador | V3: Alta
B4: Metadatos de la oficina del CDO | C4: Data Officer | S4: NO | T4: Calculado | U4: Dimensión | V4: Media
B5: Validaciones | C5: Data Owner y Data Custodian | V5: Baja
B6: Metadatos funcionales con soporte técnico | C6: Data Custodian
B7: Metadatos técnicos | C7: Data Custodian
B8: Campo formulado | C8: Data Officer

Sheet 1. Conceptos de Negocio
B1: Caso de Uso | C1: Codigo de dominio | D1: Nombre del dominio | E1: Codigo del subdominio | F1: Nombre del subdominio | G1: Nombre del subdominio OMG | H1: Concepto de negocio | I1: Término de Negocio | J1: Código de Entidad del Dato | K1: Data Owner | L1: Dato Critico | M1: Personal | N1: Sensible | O1: Definición de negocio | P1: Tipo de Dato | Q1: Indicadores empleados en el cálculo | R1: Lógica de cálculo | S1: Ejemplo de valores del Entidad del Dato | T1: Prioridad del Entidad de Dato | U1: ¿Indicador/ Dimensión? | V1: Periodicidad de Generación | W1: Áreas usuarias del dato | X1: Validado por Data Owner | Y1: Responsable de la actualización en el Diccionario Negocio
B2: Caso de uso que corresponde / Proyecto estratégico | C2: Código del dominio de datos al cual pertenece el Entidad de Dato | D2: Nombre del dominio de datos al cual pertenece el Concepto de Negocio | E2: Código del subdominio de datos al cual pertenece el Concepto de Negocio | F2: Nombre del subdominio de datos al cual pertenece el Concepto de Negocio | G2: Nombre del subdominio de datos en OMG | H2: Nombre asignado a cierta definición por la unidad de Negocio | I2: Nombre único con el cual el Negocio identifica al Entidad de Dato | J2: Identificador único secuencial, asignado al Entidad de Dato por Data Officer | K2: Nombre de la persona responsable de la gestión del dato. | L2: Dato critico: Si el dato es de uso Transversal/Regulado/Toma de decisiones. | M2: Es dato personal si me permite identificar directamente a una persona natural. | N2: Tipificación de datos que requieren un tratamiento especial por su sinsibilidad. Ej: diagnóstico médico, N°tarjeta, sueldo del colaborador/cliente. | O2: Concepto definido por el negocio para la Entidad de dato. Contiene las propiedades, características y exclusiones relacionadas al dato, y lógicas necesarias para su entendimiento. | P2: Definir si el dato es Origen: No sufre ninguna transformación Calculado: Resultado de alguna transformación | Q2: Datos utilizados en el cálculo de un indicador. | R2: Descripción resumida del cálculo realizado | S2: Valores del concepto como ejemplo y/o referencia | T2: Indica la prioridad de acuerdo a: Alta: Dato se envía a un ente regulador o algún comité directivo Media: El dato se comparte con otras áreas Baja: El dato es de uso interno | U2: Define si el Concepto de Negocio es un indicador o una dimensión | V2: Frecuencia de generación del dato | W2: Lista de áreas que solicitan el dato. | X2: Una vez revisado por el Data Owner se coloca Sí en señal de conformidad con la definición | Y2: Nombre del colaborador que actualizó el dato
A3: =TEXT(ROW()-2, "00000") -> 00001 | B3: CRM | C3: D001 | D3: Persona | E3: S001 | F3: Cliente | G3: Party Role | H3: Información del cliente | I3: Cliente | J3: =B3&A3 -> CRM00001 | K3: Gaudy Sanchez | L3: SÍ | M3: SÍ | N3: NO | O3: Contratante, asegurado o beneficiario incluido en Póliza vigente de algún producto de la empresa. | P3: Origen | Q3: No aplica | R3: No aplica | S3: María Uriarte Suárez | T3: Alta | U3: Dimensión | V3: A demanda | W3: - NO | X3: SÍ | Y3: Gobierno de Datos
A4: =TEXT(ROW()-2, "00000") -> 00002 | B4: CRM | C4: D001 | D4: Persona | E4: S001 | F4: Cliente | G4: Party | H4: Información del cliente | I4: Tipo de persona | J4: =B4&A4 -> CRM00002 | K4: Gaudy Sanchez | L4: SÍ | M4: NO | N4: NO | O4: Clasificación de cualquier individuo (persona natural) u organización (persona jurídica) de interés para el análisis de los negocios que desarrolla la Compañía. | P4: Origen | Q4: No aplica | R4: No aplica | S4: 1: Persona natural 2: Persona jurídica | T4: Alta | U4: Dimensión | V4: A demanda | W4: - Marketing - FFVV - Retención de cartera - CX | X4: SÍ | Y4: Gobierno de Datos
A5: =TEXT(ROW()-2, "00000") -> 00003 | B5: CRM | C5: D001 | D5: Persona | E5: S001 | F5: Cliente | G5: Party | H5: Información del cliente | I5: Documento de Identidad | J5: =B5&A5 -> CRM00003 | K5: Gaudy Sanchez | L5: SÍ | M5: SÍ | N5: NO | O5: Toda mención a documento de identidad deberá ser considerado dependiendo de lo detallado seguidamente: Tipo de persona - Documento de identidad. - Natural Peruano: Documento Nacional de Identidad (DNI). - Natural Extranjero: Carné de extranjería - Natural Extranjero no residente: Pasaporte. - Jurídica Peruano: Registro Único de Contribuyente (RUC). | P5: Origen | Q5: No aplica | R5: No aplica | S5: DNI: 10318698 RUC: 20123456789 CE: 12345678 Pasaporte: Y12345678 | T5: Alta | U5: Dimensión | V5: A demanda | W5: - Marketing - FFVV - Retencion de cartera - CX | X5: SÍ | Y5: Gobierno de Datos
A6: =TEXT(ROW()-2, "00000") -> 00004 | B6: CRM | C6: D001 | D6: Persona | E6: S001 | F6: Cliente | G6: Grouping | H6: Información empresarial | I6: Grupo económico | J6: =B6&A6 -> CRM00004 | K6: Gaudy Sanchez | L6: NO | M6: NO | N6: NO | O6: Conjunto de personas jurídicas, en la que alguna de ellas ejerce control sobre la o las demás, o cuando el control sobre las personas jurídicas corresponde a una o varias personas naturales que actúan como una unidad de decisión. | P6: Origen | Q6: No aplica | R6: No aplica | S6: EXPLOT MINA, CANTERA, PETR GAS | T6: Baja | U6: Dimensión | V6: A demanda | W6: - NO | X6: SÍ | Y6: Gobierno de Datos
A7: =TEXT(ROW()-2, "00000") -> 00005 | B7: CRM | C7: D001 | D7: Persona | E7: S001 | F7: Cliente | G7: Person | H7: Información del cliente | I7: Género | J7: =B7&A7 -> CRM00005 | K7: Gaudy Sanchez | L7: SÍ | M7: SÍ | N7: NO | O7: Identidad biológica de la persona natural. | P7: Origen | Q7: No aplica | R7: No aplica | S7: Masculino Femenino | T7: Media | U7: Dimensión | V7: A demanda | W7: - Marketing | X7: SÍ | Y7: Gobierno de Datos
A8: =TEXT(ROW()-2, "00000") -> 00006 | B8: CRM | C8: D001 | D8: Persona | E8: S001 | F8: Cliente | G8: Person | H8: Información del cliente | I8: Fecha Nacimiento | J8: =B8&A8 -> CRM00006 | K8: Gaudy Sanchez | L8: SÍ | M8: SÍ | N8: NO | O8: Tiempo específico que indica el día de nacimiento de la persona natural. | P8: Origen | Q8: No aplica | R8: No aplica | S8: 36192 | T8: Alta | U8: Dimensión | V8: A demanda | W8: - Marketing | X8: SÍ | Y8: Gobierno de Datos
A9: =TEXT(ROW()-2, "00000") -> 00007 | B9: CRM | C9: D001 | D9: Persona | E9: S001 | F9: Cliente | G9: Organization | H9: Información empresarial | I9: Tipo de compañía | J9: =B9&A9 -> CRM00007 | K9: Gaudy Sanchez | L9: SÍ | M9: NO | N9: NO | O9: Identifica si la empresa es privada o del estado | P9: Origen | Q9: No aplica | R9: No aplica | S9: Empresa estatal Empresa privada | T9: Baja | U9: Dimensión | V9: A demanda | W9: - NO | X9: SÍ | Y9: Gobierno de Datos
A10: =TEXT(ROW()-2, "00000") -> 00008 | B10: CRM | C10: D001 | D10: Persona | E10: S001 | F10: Cliente | G10: Organization | H10: Información empresarial | I10: Actividad económica | J10: =B10&A10 -> CRM00008 | K10: Gaudy Sanchez | L10: SÍ | M10: NO | N10: NO | O10: Es la ocupación formal desarrollada por una entidad, persona natural con negocio o persona jurídica, mediante la cual ofrece bienes o servicios. | P10: Origen | Q10: No aplica | R10: No aplica | S10: 4630: VENTA AL POR MAYOR DE ALIMENTO 4641: VENTA AL POR MAYOR DE PRODUCTO | T10: Baja | U10: Dimensión | V10: A demanda | W10: - NO | X10: SÍ | Y10: Gobierno de Datos
A11: =TEXT(ROW()-2, "00000") -> 00009 | B11: CRM | C11: D001 | D11: Persona | E11: S001 | F11: Cliente | G11: Party Role | H11: Información del cliente | I11: Estado del Cliente | J11: =B11&A11 -> CRM00009 | K11: Gaudy Sanchez | L11: SÍ | M11: NO | N11: NO | O11: El estado refleja la situación, o condición, de una entidad relacionada en un momento dado o durante una duración determinada. | P11: Origen | Q11: No aplica | R11: No aplica | S11: 1: Activo 2. Inactivo 3: Bloqueado | T11: Alta | U11: Dimensión | V11: A demanda | W11: - Marketing - FFVV - Retencion de cartera | X11: SÍ | Y11: Gobierno de Datos
A12: =TEXT(ROW()-2, "00000") -> 00010 | B12: CRM | C12: D001 | D12: Persona | E12: S001 | F12: Cliente | G12: Party Role | H12: Información del cliente | I12: Motivo de bloqueo | J12: =B12&A12 -> CRM00010 | K12: Gaudy Sanchez | L12: SÍ | M12: NO | N12: NO | O12: Es la razón registrada para restringir temporalmente o de manera permanente la operatividad del cliente en los sistemas internos. Este motivo explica por qué el cliente no puede realizar ciertos procesos comerciales o transaccionales. | P12: Origen | Q12: No aplica | R12: No aplica | S12: Fraude Muerte | T12: Media | U12: Dimensión | V12: A demanda | W12: - NO | X12: SÍ | Y12: Gobierno de Datos
A13: =TEXT(ROW()-2, "00000") -> 00011 | B13: CRM | C13: D001 | D13: Persona | E13: S001 | F13: Cliente | G13: Party Communication​ | H13: Información del cliente | I13: Correo electrónico | J13: =B13&A13 -> CRM00011 | K13: Gaudy Sanchez | L13: SÍ | M13: SÍ | N13: NO | O13: Es un servicio de red que permite a los usuarios enviar y recibir mensajes mediante redes de comunicación electrónica. | P13: Origen | Q13: No aplica | R13: No aplica | S13: aaaa@gmail.com | T13: Alta | U13: Dimensión | V13: A demanda | W13: - Marketing - FFVV - Retencion de cartera - CX | X13: SÍ | Y13: Gobierno de Datos
A14: =TEXT(ROW()-2, "00000") -> 00012 | B14: CRM | C14: D001 | D14: Persona | E14: S001 | F14: Cliente | G14: Party Communication​ | H14: Información del cliente | I14: Teléfono | J14: =B14&A14 -> CRM00012 | K14: Gaudy Sanchez | L14: SÍ | M14: SÍ | N14: NO | O14: El teléfono es un tipo de Punto de Contacto que es un instrumento para reproducir sonidos a distancia; específicamente, uno en el que el sonido se convierte en impulsos eléctricos para su transmisión (ya sea por cable o ondas de radio) y luego se vuelve a convertir en sonido para ser utilizado por el punto de contacto receptor. | P14: Origen | Q14: No aplica | R14: No aplica | S14: 922927471 | T14: Alta | U14: Dimensión | V14: A demanda | W14: - Marketing - FFVV - Retencion de cartera - CX | X14: SÍ | Y14: Gobierno de Datos
A15: =TEXT(ROW()-2, "00000") -> 00013 | B15: CRM | C15: D001 | D15: Persona | E15: S001 | F15: Cliente | G15: Party Communication​ | H15: Información del cliente | I15: Dirección | J15: =B15&A15 -> CRM00013 | K15: Gaudy Sanchez | L15: SÍ | M15: SÍ | N15: NO | O15: Punto dentro de la geografía en donde se ubica una entidad. | P15: Origen | Q15: No aplica | R15: No aplica | S15: Mz. L, Lt. 21, Av. Miguel iglesias, Lima, SJM | T15: Alta | U15: Dimensión | V15: A demanda | W15: - Marketing - FFVV | X15: SÍ | Y15: Gobierno de Datos
A16: =TEXT(ROW()-2, "00000") -> 00014 | B16: CRM | C16: D001 | D16: Persona | E16: S002 | F16: Corredor | G16: Party Role | H16: Relación comercial | I16: Intermediario | J16: =B16&A16 -> CRM00014 | K16: Arturo Yaipen | L16: SÍ | M16: NO | N16: NO | O16: Persona natural o jurídica que intermedia en la colocación de productos emitidos por compañías de seguros, con clientes personas naturales o jurídicas. Su relación con la compañía es mediante un contrato de intermediación o agenciamiento. | P16: Origen | Q16: No aplica | R16: No aplica | S16: ADRIGAS E.I.R.L Ramirez Rojas, Ronaldo Hugo | T16: Alta | U16: Dimensión | V16: A demanda | W16: - Comercial - Emisión - Riesgos - Tecnica | X16: SÍ | Y16: Gobierno de Datos
A17: =TEXT(ROW()-2, "00000") -> 00015 | B17: CRM | C17: D001 | D17: Persona | E17: S001 | F17: Cliente | G17: Party Role | H17: Información del cliente | I17: Rol persona | J17: =B17&A17 -> CRM00015 | K17: Gaudy Sanchez | L17: NO | M17: NO | N17: NO | O17: Definido como el rol que desempeña la persona en la empresa, si es colaborador, cliente y/o agente (bróker o comercializador). | P17: Origen | Q17: No aplica | R17: No aplica | S17: Cliente Personal Agente | T17: Media | U17: Dimensión | V17: A demanda | W17: - Marketing - FFVV - Retencion de cartera - CX | X17: SÍ | Y17: Gobierno de Datos
A18: =TEXT(ROW()-2, "00000") -> 00016 | B18: CRM | C18: D001 | D18: Persona | E18: S001 | F18: Cliente | G18: Party Role | H18: Información del cliente | I18: Rol cliente | J18: =B18&A18 -> CRM00016 | K18: Gaudy Sanchez | L18: NO | M18: NO | N18: NO | O18: Indica el rol que cumple el cliente ante una póliza. | P18: Origen | Q18: No aplica | R18: No aplica | S18: 1. Asegurado 2. Contratante 3. Pagador 4. Beneficiario 5. Dependiente 6. Agrupador 7. Beneficiario Contingente | T18: Media | U18: Dimensión | V18: A demanda | W18: - NO | X18: SÍ | Y18: Gobierno de Datos
A19: 00013 | B19: CRM | C19: D001 | D19: Persona | E19: S001 | F19: Cliente | G19: Party Role | H19: Participante de la póliza | I19: Asegurado | J19: CRM00013 | K19: Gaudy Sanchez | L19: SÍ | M19: NO | N19: NO | O19: Persona o bien que, mediante el pago de una prima, recibe la protección del Asegurador, quien se obliga a indemnizar las pérdidas o los perjuicios que puedan sobrevenir a la otra parte en casos determinados, fortuitos o de fuerza mayor. Es menester aclarar que en el Seguro de Vida, la persona a quien se le llama "Asegurado" es aquella cuya cabeza se contrata el seguro, la cual no tiene que ser forzosamente la misma que la del contratante o persona que estipula el seguro o firma la Póliza con el Asegurador obligándose a pagar las primas del seguro. | P19: Origen | Q19: No aplica | R19: No aplica | S19: María Uriarte Suárez | T19: Alta | U19: Dimensión | V19: A demanda | W19: - NO | X19: SÍ | Y19: Gobierno de Datos
A20: 00014 | B20: CRM | C20: D001 | D20: Persona | E20: S001 | F20: Cliente | G20: Party Role | H20: Participante de la póliza | I20: Contratante | J20: CRM00014 | K20: Gaudy Sanchez | L20: NO | M20: NO | N20: NO | O20: Persona natural o jurídica u organismo del Estado determinado en las condiciones particulares de la póliza, que contrata el seguro y se obliga al pago de la prima. Puede ser también el Asegurado. El contratante es el único que puede solicitar modificaciones a la póliza, asimismo es el que propone los montos asegurados y los riesgos que necesita. En el caso de un seguro individual puede además tener la calidad de asegurado. | P20: Origen | Q20: No aplica | R20: No aplica | S20: María Uriarte Suárez La Positiva Seguros | T20: Media | U20: Dimensión | V20: A demanda | W20: - NO | X20: SÍ | Y20: Gobierno de Datos
A21: 00015 | B21: CRM | C21: D001 | D21: Persona | E21: S001 | F21: Cliente | G21: Party Role | H21: Participante de la póliza | I21: Pagador | J21: CRM00015 | K21: Gaudy Sanchez | L21: NO | M21: NO | N21: NO | O21: Persona responsable del pago de la prima (puede o no coincidir con el contratante). | P21: Origen | Q21: No aplica | R21: No aplica | S21: María Uriarte Suárez La Positiva Seguros | T21: Media | U21: Dimensión | V21: A demanda | W21: - NO | X21: SÍ | Y21: Gobierno de Datos
A22: 00016 | B22: CRM | C22: D001 | D22: Persona | E22: S001 | F22: Cliente | G22: Party Role | H22: Participante de la póliza | I22: Benficiario | J22: CRM00016 | K22: Gaudy Sanchez | L22: SÍ | M22: NO | N22: NO | O22: En los seguros que cubran el riesgo de fallecimiento de una persona, el plazo de prescripción para el beneficiario se computa desde que este conoce la existencia del beneficio. | P22: Origen | Q22: No aplica | R22: No aplica | S22: María Uriarte Suárez | T22: Alta | U22: Dimensión | V22: A demanda | W22: - NO | X22: SÍ | Y22: Gobierno de Datos
A23: 00018 | B23: CRM | C23: D001 | D23: Persona | E23: S001 | F23: Cliente | G23: Party Role | H23: Participante de la póliza | I23: Agrupador | J23: CRM00018 | K23: Gaudy Sanchez | L23: NO | M23: NO | N23: NO | O23: Identificador que agrupa pólizas bajo un mismo grupo económico. | P23: Origen | Q23: No aplica | R23: No aplica | S23: G.E. Marina de Guerra del Perú | T23: Media | U23: Dimensión | V23: A demanda | W23: - NO | X23: SÍ | Y23: Gobierno de Datos
A24: 00018 | B24: CRM | C24: D001 | D24: Persona | E24: S001 | F24: Cliente | G24: Party Relationship | H24: Relación entre personas | I24: Parentesco | J24: CRM00018 | K24: Gaudy Sanchez | L24: SÍ | M24: NO | N24: NO | O24: Relación familiar o vínculo legal que existe entre el titular de la póliza y otra persona asociada a ella, como un beneficiario, dependiente o asegurado adicional. | P24: Origen | Q24: No aplica | R24: No aplica | S24: Hermano/a Padre Madre Hijo Concubina | T24: Alta | U24: Dimensión | V24: A demanda | W24: - NO | X24: NO | Y24: Gobierno de Datos
A25: =TEXT(ROW()-2, "00000") -> 00023 | B25: CRM | C25: D002 | D25: Persona | E25: S012 | F25: Cliente | G25: Person | H25: Información de la persona | I25: Fecha de fallecimiento | J25: =B25&A25 -> CRM00023 | K25: RRGG (Patricia Paredes) SOAT (C. Illanes) VIDA (Victor Lazo) | L25: SÍ | M25: SÍ | N25: NO | O25: Fecha en la que falleció la persona asegurada y/o afectada. | P25: Origen | Q25: No aplica | R25: No aplica | S25: 36192 | T25: Alta | U25: Dimensión | V25: A demanda | X25: SÍ | Y25: Gobierno de Datos
A26: =TEXT(ROW()-2, "00000") -> 00024 | B26: CRM | C26: D002 | D26: Persona | E26: S015 | F26: Cliente | G26: Party_Role | H26: Participante del siniestro | I26: Persona afectada | J26: =B26&A26 -> CRM00024 | K26: RRGG (Patricia Paredes) SALUD (Eva Tomas) AUTOS (C. Illanes) SOAT (C. Illanes) VIDA (Victor Lazo) | L26: SÍ | M26: SÍ | N26: NO | O26: Persona natural y/o jurídica afectada que sufrió un accidente, daño o pérdida. | P26: Origen | Q26: No aplica | R26: No aplica | S26: Ana Rivas Uriarte | T26: Alta | U26: Dimensión | V26: A demanda | X26: SÍ | Y26: Gobierno de Datos
A27: =TEXT(ROW()-2, "00000") -> 00025 | B27: CRM | C27: D002 | D27: Persona | E27: S018 | F27: Cliente | G27: Party_Role | H27: Participante del siniestro | I27: Conductor | J27: =B27&A27 -> CRM00025 | K27: AUTOS (C. Illanes) SOAT (C. Illanes) | L27: SÍ | M27: SÍ | N27: NO | O27: Nombre del conductor del vehiculo participante en el siniestro. | P27: Origen | Q27: No aplica | R27: No aplica | S27: Ana Rivas Uriarte | T27: Alta | U27: Dimensión | V27: A demanda | X27: SÍ | Y27: Gobierno de Datos
A28: =TEXT(ROW()-2, "00000") -> 00026 | B28: CRM | C28: D002 | D28: Persona | E28: S021 | F28: Proveedor | G28: Party_Role | H28: Participante del siniestro | I28: Médico | J28: =B28&A28 -> CRM00026 | K28: SALUD (Eva Tomas) VIDA (Victor Lazo) | L28: NO | M28: SÍ | N28: NO | O28: Profesional de la salud que certifica oficialmente el fallecimiento o la invalidez del asegurado. | P28: Origen | Q28: No aplica | R28: No aplica | S28: Ana Rivas Uriarte | T28: Baja | U28: Dimensión | V28: A demanda | X28: SÍ | Y28: Gobierno de Datos
A29: =TEXT(ROW()-2, "00000") -> 00027 | B29: CRM | C29: D002 | D29: Persona | E29: S022 | F29: Cliente | G29: Organization | H29: Información del participante en el siniestro | I29: Actividad SCTR | J29: =B29&A29 -> CRM00027 | K29: VIDA (Victor Lazo) | L29: SÍ | M29: NO | N29: NO | O29: Clasificación de la actividad económica del asegurado, según lo establecido en el Seguro Complementario de Trabajo de Riesgo (SCTR), indicando si corresponde a minería o no minería. | P29: Calculado | Q29: CIIU --> Código CIIU M --> Minería o No minería | R29: CASE WHEN substr(CIIU,1,2) IN ('05','06','07','08','09') THEN 'Minería' ELSE 'No minería' END AS M | S29: Minería No minería | T29: Alta | U29: Dimensión | V29: A demanda | X29: SÍ | Y29: Gobierno de Datos
A30: =TEXT(ROW()-2, "00000") -> 00028 | B30: CRM | C30: D002 | D30: Póliza | E30: S003 | F30: Emisión y Transformación Colocaciones | G30: Party Role | H30: Relación comercial | I30: Canal de venta | J30: =B30&A30 -> CRM00028 | K30: VIDA (Victor Lazo) SALUD (Juan Camayoc) | L30: NO | M30: NO | N30: NO | O30: Medio o vía a través del cual se concretó la venta de la póliza. | P30: Origen | Q30: No aplica | R30: No tiene cálculo | S30: FFVV | T30: Media | U30: Dimensión | V30: A demanda | X30: SÍ | Y30: Gobierno de Datos
A31: =TEXT(ROW()-2, "00000") -> 00029 | B31: CRM | C31: D002 | D31: Póliza | E31: S003 | F31: Emisión y Transformación Colocaciones | G31: Organization | H31: Información de póliza | I31: Oficina | J31: =B31&A31 -> CRM00029 | K31: VIDA (Victor Lazo) RRGG (Daniel Iwamoto) SALUD (Juan Camayoc) AUTOS (Juan Calixtro) SOAT (Jorge Shimizu) | L31: SÍ | M31: NO | N31: NO | O31: Establecimientos físicos a través de los cuales la empresa atiende al público para realizar la gestión de la póliza. | P31: Origen | Q31: No aplica | R31: No tiene cálculo | S31: San Isidro Oficina | T31: Media | U31: Dimensión | V31: A demanda | X31: SÍ | Y31: Gobierno de Datos
A32: =TEXT(ROW()-2, "00000") -> 00030 | B32: MidlleTier | C32: D002 | D32: Persona | E32: S022 | F32: Cliente | H32: Información del cliente | I32: País | J32: =B32&A32 -> MidlleTier00030 | K32: Gaudy Sanchez | L32: NO | M32: SÍ | N32: NO | O32: Entidad geopolítica que identifica el Estado soberano donde se encuentra ubicado el domicilio principal del cliente o de la persona registrada en el sistema. | P32: Origen | Q32: No aplica | R32: No aplica | S32: Perú | T32: Baja | U32: Dimensión | V32: A demanda | W32: No aplica | X32: NO | Y32: Gobierno de Datos
A33: =TEXT(ROW()-2, "00000") -> 00031 | B33: MidlleTier | C33: D002 | D33: Persona | E33: S022 | F33: Cliente | H33: Información del cliente | I33: Departamento | J33: =B33&A33 -> MidlleTier00031 | K33: Gaudy Sanchez | L33: SÍ | M33: SÍ | N33: NO | O33: División administrativa de primer nivel que identifica la región del estado peruano donde se encuentra ubicado el domicilio del cliente o de la persona registrada. | P33: Origen | Q33: No aplica | R33: No aplica | S33: Lima | T33: Media | U33: Dimensión | V33: A demanda | W33: Marketing, Experiencia del cliente, Plataforma, Televentas, FFVV Digital | X33: NO | Y33: Gobierno de Datos
A34: =TEXT(ROW()-2, "00000") -> 00032 | B34: MidlleTier | C34: D002 | D34: Persona | E34: S022 | F34: Cliente | H34: Información del cliente | I34: Provincia | J34: =B34&A34 -> MidlleTier00032 | K34: Gaudy Sanchez | L34: SÍ | M34: SÍ | N34: NO | O34: División administrativa de segundo nivel que identifica la provincia del estado peruano donde se encuentra ubicado el domicilio del cliente o de la persona registrada. | P34: Origen | Q34: No aplica | R34: No aplica | S34: Lima | T34: Media | U34: Dimensión | V34: A demanda | W34: Marketing, Experiencia del cliente | X34: NO | Y34: Gobierno de Datos
A35: =TEXT(ROW()-2, "00000") -> 00033 | B35: MidlleTier | C35: D002 | D35: Persona | E35: S022 | F35: Cliente | H35: Información del cliente | I35: Distrito | J35: =B35&A35 -> MidlleTier00033 | K35: Gaudy Sanchez | L35: SÍ | M35: SÍ | N35: NO | O35: División administrativa de tercer nivel que identifica el distrito del estado peruano donde se encuentra ubicado el domicilio del cliente o de la persona registrada. | P35: Origen | Q35: No aplica | R35: No aplica | S35: Surco | T35: Media | U35: Dimensión | V35: A demanda | W35: Marketing, Experiencia del cliente | X35: NO | Y35: Gobierno de Datos
A36: =TEXT(ROW()-2, "00000") -> 00034 | B36: MidlleTier | C36: D002 | D36: Persona | E36: S022 | F36: Cliente | G36: Person | H36: Información del cliente | I36: Edad | J36: =B36&A36 -> MidlleTier00034 | K36: Gaudy Sanchez | L36: SÍ | M36: SÍ | N36: NO | O36: Cantidad de años cumplidos de la persona, calculada a partir de su fecha de nacimiento a la fecha actual. | P36: Calculado | Q36: - FN: Fecha de nacimiento, - FA: Fecha actual | R36: FA - FN | S36: 20 | T36: Baja | U36: Dimensión | V36: A demanda | W36: No aplica | X36: NO | Y36: Gobierno de Datos
A37: =TEXT(ROW()-2, "00000") -> 00035 | B37: MidlleTier | C37: D002 | D37: Persona | E37: S022 | F37: Cliente | G37: Person | H37: Información del cliente | I37: Estado Civil | J37: =B37&A37 -> MidlleTier00035 | K37: Gaudy Sanchez | L37: NO | M37: SÍ | N37: NO | O37: Condición legal que identifica la situación civil de la persona (soltero, casado, conviviente, divorciado, viudo, entre otros), conforme a la normativa vigente. | P37: Origen | Q37: No aplica | R37: No aplica | S37: Soltero | T37: Baja | U37: Dimensión | V37: A demanda | W37: No aplica | X37: NO | Y37: Gobierno de Datos
A38: =TEXT(ROW()-2, "00000") -> 00036 | B38: MidlleTier | C38: D002 | D38: Persona | E38: S022 | F38: Corredor | G38: Party_Role | H38: Relación comercial | I38: Comercializador | J38: =B38&A38 -> MidlleTier00036 | K38: Arturo Yaipen | L38: SÍ | M38: NO | N38: NO | O38: Persona jurídica que participa en la colocación y venta de pólizas de seguros, actuando como intermediario en el proceso de distribución de productos aseguradores. | P38: Origen | Q38: No aplica | R38: No aplica | S38: Bodega ABC | T38: Baja | U38: Dimensión | V38: A demanda | W38: No aplica | X38: SÍ | Y38: Gobierno de Datos
A39: =TEXT(ROW()-2, "00000") -> 00037 | B39: MidlleTier | C39: D002 | D39: Persona | E39: S022 | F39: Corredor | H39: Relación comercial | I39: Banca-Seguros | J39: =B39&A39 -> MidlleTier00037 | K39: Arturo Yaipen | L39: SÍ | M39: NO | N39: NO | O39: Canal de distribución mediante el cual una entidad financiera comercializa productos de seguros a través de su red de agencias, plataformas o medios digitales, en virtud de un convenio con la aseguradora. | P39: Origen | Q39: No aplica | R39: No aplica | S39: BBVA Perú | T39: Alta | U39: Dimensión | V39: Trimestral | W39: - Suscripción - Emisión - Cobranzas - Comercial - CNT - Auditoría | X39: SÍ | Y39: Gobierno de Datos
A40: =TEXT(ROW()-2, "00000") -> 00038 | B40: MidlleTier | C40: D002 | D40: Persona | E40: S022 | F40: Proveedor | G40: Party_Role | H40: Información del proveedor | I40: Proveedor | J40: =B40&A40 -> MidlleTier00038 | K40: Alvaro Kutsuma | L40: SÍ | M40: SÍ | N40: NO | O40: Persona natural o jurídica que brinda a La Positiva servicios de carácter administrativo o técnico indispensables para la operación del negocio, atención de los clientes, procesos de suscripción, gestión de siniestros o servicios complementarios. | P40: Origen | Q40: No aplica | R40: No aplica | S40: Navarrete Flexo Impresiones Hospital Rebagliati | T40: Media | U40: Dimensión | V40: A demanda | W40: - Toda LP | X40: SÍ | Y40: Gobierno de Datos
...

Sheet 2. Reglas de Calidad
A1: Iniciativa | B1: Caso de uso | C1: ID Regla de calidad | D1: Término de Negocio | E1: Tabla del Entidad de Dato (OMG) | F1: Campo del Entidad de Dato (OMG) | G1: Nombre del Entidad de Dato | H1: Descripción de Regla de calidad | I1: Tipo de regla de calidad | J1: Cumplimiento regla de Calidad (CORE) | K1: Principio de calidad asociado | L1: Umbral Superior | M1: Umbral Inferior | N1: Periodicidad | O1: Aplicación | P1: Data Owner | Q1: Validado por Data Owner
A2: Iniciativa | B2: Caso de uso que corresponde | C2: Identificador de Regla de Calidad | E2: Nombre de la entidad que se visualiza en la documentación de OMG | F2: Campo de la entidad que se visualiza en la documentación de OMG | G2: Nombre único con el cual el Negocio identifica a la Entidad de Dato | H2: Describir las propiedades, características y exclusiones relacionadas al dato, y lógicas necesarias para su entendimiento | I2: Indica si se trata de una regla básica o una regla experta | J2: Validar si la regla se cumple dentro del CORE. | K2: Se debe indicar el principio de calidad al que se hace referencia (Consistencia, completitud, etc) | L2: Indica el límite superior sobre los valores que puede tomar el dato | M2: Indica el límite inferior sobre los valores que puede tomar el dato | N2: Frecuencia con la que se aplica | O2: Nombre del aplicativo en el que se consulta/visualiza el dato | P2: Nombre de la persona responsable de la gestión del dato. | Q2: Una vez revisado por el Data Owner se coloca Sí en señal de conformidad con la definición
A3: CRM | B3: CRM | C3: =+UPPER(MID(B3,1,3))&"00"&COUNTA(B$3:B3) -> CRM001 | D3: Cliente | E3: Customer | F3: Party_Identifier | G3: Id Cliente | H3: Sin duplicidad (Valor único). | I3: Básica | J3: SÍ | K3: Consistencia | L3: 1 | M3: 0.98 | N3: A demanda | O3: INSIS, VTIME, INSUNIX | P3: Gaudy Sanchez | Q3: SÍ
A4: CRM | C4: =+UPPER(MID(B4,1,3))&"00"&COUNTA(B$3:B4) -> 001 | D4: Cliente | E4: Customer | F4: Party_Identifier | G4: Id Cliente | H4: Debe ser entero positivo.(Dependiendo del Core el Id de cliente tiene letras) | I4: Básica | J4: SÍ | K4: Validez | L4: 1 | M4: 0.98 | N4: A demanda | O4: INSIS, VTIME, INSUNIX | P4: Gaudy Sanchez | Q4: SÍ
A5: CRM | C5: =+UPPER(MID(B5,1,3))&"00"&COUNTA(B$3:B5) -> 001 | D5: Cliente | E5: Customer | F5: Party_Identifier | G5: Id Cliente | H5: No debe modificarse una vez creado. | I5: Básica | J5: SÍ | K5: Integridad | L5: 1 | M5: 0.98 | N5: A demanda | O5: INSIS, VTIME, INSUNIX | P5: Gaudy Sanchez | Q5: SÍ
A6: CRM | C6: =+UPPER(MID(B6,1,3))&"00"&COUNTA(B$3:B6) -> 001 | D6: Cliente | E6: Customer | F6: Party_Identifier | G6: Id Cliente | H6: No se permiten valores vacíos o nulos. | I6: Básica | J6: SÍ | K6: Completitud | L6: 1 | M6: 0.98 | N6: A demanda | O6: INSIS, VTIME, INSUNIX | P6: Gaudy Sanchez | Q6: SÍ
A7: CRM | C7: =+UPPER(MID(B7,1,3))&"00"&COUNTA(B$3:B7) -> 001 | D7: Cliente | E7: Customer | F7: Party_Identifier | G7: Id Cliente | H7: No acepta carácteres especiales. | I7: Básica | J7: NO | K7: Validez | L7: 1 | M7: 0.98 | N7: A demanda | O7: INSIS, VTIME, INSUNIX | P7: Gaudy Sanchez | Q7: SÍ
A8: CRM | B8: CRM | C8: =+UPPER(MID(B8,1,3))&"00"&COUNTA(B$3:B8) -> CRM002 | D8: Cliente | E8: Person | F8: First_Name | G8: Primer Nombre | H8: Longitud de 40 caracteres | I8: Básica | J8: NO | K8: Validez | L8: 1 | M8: 0.98 | N8: A demanda | O8: INSIS, VTIME, INSUNIX | P8: Gaudy Sanchez | Q8: SÍ
A9: CRM | C9: =+UPPER(MID(B9,1,3))&"00"&COUNTA(B$3:B9) -> 002 | D9: Cliente | E9: Person | F9: First_Name | G9: Primer Nombre | H9: No se acepta números (0-9). | I9: Básica | J9: NO | K9: Validez | L9: 1 | M9: 0.98 | N9: A demanda | O9: INSIS, VTIME, INSUNIX | P9: Gaudy Sanchez | Q9: SÍ
A10: CRM | C10: =+UPPER(MID(B10,1,3))&"00"&COUNTA(B$3:B10) -> 002 | D10: Cliente | E10: Person | F10: First_Name | G10: Primer Nombre | H10: No se permiten valores vacíos o nulos. | I10: Básica | J10: SÍ | K10: Completitud | L10: 1 | M10: 0.98 | N10: A demanda | O10: INSIS, VTIME, INSUNIX | P10: Gaudy Sanchez | Q10: SÍ
A11: CRM | C11: =+UPPER(MID(B11,1,3))&"00"&COUNTA(B$3:B11) -> 002 | D11: Cliente | E11: Person | F11: First_Name | G11: Primer Nombre | H11: No acepta carácteres especiales, excepto: Apostrofe(') y Guiones (-). | I11: Básica | J11: NO | K11: Validez | L11: 1 | M11: 0.98 | N11: A demanda | O11: INSIS, VTIME, INSUNIX | P11: Gaudy Sanchez | Q11: SÍ
A12: CRM | C12: =+UPPER(MID(B12,1,3))&"00"&COUNTA(B$3:B12) -> 002 | D12: Cliente | E12: Person | F12: First_Name | G12: Primer Nombre | H12: No se acepta nombres de menos de 2 carácteres. | I12: Básica | J12: NO | K12: Validez | L12: 1 | M12: 0.98 | N12: A demanda | O12: INSIS, VTIME, INSUNIX | P12: Gaudy Sanchez | Q12: SÍ
A13: CRM | C13: =+UPPER(MID(B13,1,3))&"00"&COUNTA(B$3:B13) -> 002 | D13: Cliente | E13: Person | F13: First_Name | G13: Primer Nombre | H13: No se acepta saltos de línea. | I13: Básica | J13: SÍ | K13: Validez | L13: 1 | M13: 0.98 | N13: A demanda | O13: INSIS, VTIME, INSUNIX | P13: Gaudy Sanchez | Q13: SÍ
A14: CRM | C14: =+UPPER(MID(B14,1,3))&"00"&COUNTA(B$3:B14) -> 002 | D14: Cliente | E14: Person | F14: First_Name | G14: Primer Nombre | H14: No se acepta tabulaciones. | I14: Básica | J14: NO | K14: Validez | L14: 1 | M14: 0.98 | N14: A demanda | O14: INSIS, VTIME, INSUNIX | P14: Gaudy Sanchez | Q14: SÍ
A15: CRM | C15: =+UPPER(MID(B15,1,3))&"00"&COUNTA(B$3:B15) -> 002 | D15: Cliente | E15: Person | F15: First_Name | G15: Primer Nombre | H15: No debe haber más de 2 tíldes | I15: Básica | J15: NO | K15: Validez | L15: 1 | M15: 0.98 | N15: A demanda | O15: INSIS, VTIME, INSUNIX | P15: Gaudy Sanchez | Q15: SÍ
A16: CRM | C16: =+UPPER(MID(B16,1,3))&"00"&COUNTA(B$3:B16) -> 002 | D16: Cliente | E16: Person | F16: First_Name | G16: Primer Nombre | H16: Se aceptan nombres compuestos como O’BRYAN | I16: Básica | J16: NO | K16: Validez | L16: 1 | M16: 0.98 | N16: A demanda | O16: INSIS, VTIME, INSUNIX | P16: Gaudy Sanchez | Q16: SÍ
A17: CRM | C17: =+UPPER(MID(B17,1,3))&"00"&COUNTA(B$3:B17) -> 002 | D17: Cliente | E17: Person | F17: First_Name | G17: Primer Nombre | H17: Debe coincidir con documento de identifidad registrado. | I17: Experta | J17: SÍ | K17: Precisión | L17: 1 | M17: 0.98 | N17: A demanda | O17: INSIS, VTIME, INSUNIX | P17: Gaudy Sanchez | Q17: SÍ
A18: CRM | C18: =+UPPER(MID(B18,1,3))&"00"&COUNTA(B$3:B18) -> 002 | D18: Cliente | E18: Person | F18: First_Name | G18: Primer Nombre | H18: Solo aplica para persona natural. | I18: Básica | J18: SÍ | K18: Integridad | L18: 1 | M18: 0.98 | N18: A demanda | O18: INSIS, VTIME, INSUNIX | P18: Gaudy Sanchez | Q18: SÍ
A19: CRM | C19: =+UPPER(MID(B19,1,3))&"00"&COUNTA(B$3:B19) -> 002 | D19: Cliente | E19: Person | F19: First_Name | G19: Primer Nombre | H19: Los nombres no alternan mayúsculas/minúsculas de forma errática. Todo mayúsculas. | I19: Básica | J19: NO | K19: Validez | L19: 1 | M19: 0.98 | N19: A demanda | O19: INSIS, VTIME, INSUNIX | P19: Gaudy Sanchez | Q19: SÍ
A20: CRM | C20: =+UPPER(MID(B20,1,3))&"00"&COUNTA(B$3:B20) -> 002 | D20: Cliente | E20: Person | F20: First_Name | G20: Primer Nombre | H20: Un nombre no comienza con símbolos. | I20: Básica | J20: NO | K20: Validez | L20: 1 | M20: 0.98 | N20: A demanda | O20: INSIS, VTIME, INSUNIX | P20: Gaudy Sanchez | Q20: SÍ
A21: CRM | B21: CRM | C21: =+UPPER(MID(B21,1,3))&"00"&COUNTA(B$3:B21) -> CRM003 | D21: Cliente | E21: Person | F21: Middle_Name | G21: Segundo Nombre | H21: Longitud de 40 caracteres | I21: Básica | J21: NO | K21: Validez | L21: 1 | M21: 0.98 | N21: A demanda | O21: INSIS, VTIME, INSUNIX | P21: Gaudy Sanchez | Q21: SÍ
A22: CRM | C22: =+UPPER(MID(B22,1,3))&"00"&COUNTA(B$3:B22) -> 003 | D22: Cliente | E22: Person | F22: Middle_Name | G22: Segundo Nombre | H22: No se acepta números (0-9). | I22: Básica | J22: NO | K22: Validez | L22: 1 | M22: 0.98 | N22: A demanda | O22: INSIS, VTIME, INSUNIX | P22: Gaudy Sanchez | Q22: SÍ
A23: CRM | C23: =+UPPER(MID(B23,1,3))&"00"&COUNTA(B$3:B23) -> 003 | D23: Cliente | E23: Person | F23: Middle_Name | G23: Segundo Nombre | H23: Se permiten valores vacíos o nulos. | I23: Básica | J23: SÍ | K23: Completitud | L23: 1 | M23: 0.98 | N23: A demanda | O23: INSIS, VTIME, INSUNIX | P23: Gaudy Sanchez | Q23: SÍ
A24: CRM | C24: =+UPPER(MID(B24,1,3))&"00"&COUNTA(B$3:B24) -> 003 | D24: Cliente | E24: Person | F24: Middle_Name | G24: Segundo Nombre | H24: No acepta carácteres especiales, excepto: Apostrofe(') y Guiones (-). | I24: Básica | J24: NO | K24: Validez | L24: 1 | M24: 0.98 | N24: A demanda | O24: INSIS, VTIME, INSUNIX | P24: Gaudy Sanchez | Q24: SÍ
A25: CRM | C25: =+UPPER(MID(B25,1,3))&"00"&COUNTA(B$3:B25) -> 003 | D25: Cliente | E25: Person | F25: Middle_Name | G25: Segundo Nombre | H25: No se acepta nombres de menos de 2 carácteres. | I25: Básica | J25: NO | K25: Validez | L25: 1 | M25: 0.98 | N25: A demanda | O25: INSIS, VTIME, INSUNIX | P25: Gaudy Sanchez | Q25: SÍ
A26: CRM | C26: =+UPPER(MID(B26,1,3))&"00"&COUNTA(B$3:B26) -> 003 | D26: Cliente | E26: Person | F26: Middle_Name | G26: Segundo Nombre | H26: No se acepta saltos de línea. | I26: Básica | J26: SÍ | K26: Validez | L26: 1 | M26: 0.98 | N26: A demanda | O26: INSIS, VTIME, INSUNIX | P26: Gaudy Sanchez | Q26: SÍ
A27: CRM | C27: =+UPPER(MID(B27,1,3))&"00"&COUNTA(B$3:B27) -> 003 | D27: Cliente | E27: Person | F27: Middle_Name | G27: Segundo Nombre | H27: No se acepta tabulaciones. | I27: Básica | J27: NO | K27: Validez | L27: 1 | M27: 0.98 | N27: A demanda | O27: INSIS, VTIME, INSUNIX | P27: Gaudy Sanchez | Q27: SÍ
A28: CRM | C28: =+UPPER(MID(B28,1,3))&"00"&COUNTA(B$3:B28) -> 003 | D28: Cliente | E28: Person | F28: Middle_Name | G28: Segundo Nombre | H28: No debe haber más de 2 tíldes | I28: Básica | J28: NO | K28: Validez | L28: 1 | M28: 0.98 | N28: A demanda | O28: INSIS, VTIME, INSUNIX | P28: Gaudy Sanchez | Q28: SÍ
A29: CRM | C29: =+UPPER(MID(B29,1,3))&"00"&COUNTA(B$3:B29) -> 003 | D29: Cliente | E29: Person | F29: Middle_Name | G29: Segundo Nombre | H29: Se aceptan nombres compuestos como O’BRYAN | I29: Básica | J29: SÍ | K29: Validez | L29: 1 | M29: 0.98 | N29: A demanda | O29: INSIS, VTIME, INSUNIX | P29: Gaudy Sanchez | Q29: SÍ
A30: CRM | C30: =+UPPER(MID(B30,1,3))&"00"&COUNTA(B$3:B30) -> 003 | D30: Cliente | E30: Person | F30: Middle_Name | G30: Segundo Nombre | H30: Debe coincidir con documento de identifidad registrado. | I30: Experta | J30: SÍ | K30: Precisión | L30: 1 | M30: 0.98 | N30: A demanda | O30: INSIS, VTIME, INSUNIX | P30: Gaudy Sanchez | Q30: SÍ
A31: CRM | C31: =+UPPER(MID(B31,1,3))&"00"&COUNTA(B$3:B31) -> 003 | D31: Cliente | E31: Person | F31: Middle_Name | G31: Segundo Nombre | H31: Solo aplica para persona natural. | I31: Básica | J31: SÍ | K31: Integridad | L31: 1 | M31: 0.98 | N31: A demanda | O31: INSIS, VTIME, INSUNIX | P31: Gaudy Sanchez | Q31: SÍ
A32: CRM | C32: =+UPPER(MID(B32,1,3))&"00"&COUNTA(B$3:B32) -> 003 | D32: Cliente | E32: Person | F32: Middle_Name | G32: Segundo Nombre | H32: Los nombres no alternan mayúsculas/minúsculas de forma errática. Todo mayúsculas. | I32: Básica | J32: NO | K32: Validez | L32: 1 | M32: 0.98 | N32: A demanda | O32: INSIS, VTIME, INSUNIX | P32: Gaudy Sanchez | Q32: SÍ
A33: CRM | B33: CRM | C33: =+UPPER(MID(B33,1,3))&"00"&COUNTA(B$3:B33) -> CRM004 | D33: Cliente | E33: Person | F33: Last_Name | G33: Apellido Paterno | H33: Longitud de 40 caracteres | I33: Básica | J33: NO | K33: Validez | L33: 1 | M33: 0.98 | N33: A demanda | O33: INSIS, VTIME, INSUNIX | P33: Gaudy Sanchez | Q33: SÍ
A34: CRM | C34: =+UPPER(MID(B34,1,3))&"00"&COUNTA(B$3:B34) -> 004 | D34: Cliente | E34: Person | F34: Last_Name | G34: Apellido Paterno | H34: No se acepta números (0-9). | I34: Básica | J34: NO | K34: Validez | L34: 1 | M34: 0.98 | N34: A demanda | O34: INSIS, VTIME, INSUNIX | P34: Gaudy Sanchez | Q34: SÍ
A35: CRM | C35: =+UPPER(MID(B35,1,3))&"00"&COUNTA(B$3:B35) -> 004 | D35: Cliente | E35: Person | F35: Last_Name | G35: Apellido Paterno | H35: No se permiten valores vacíos o nulos. | I35: Básica | J35: SÍ | K35: Completitud | L35: 1 | M35: 0.98 | N35: A demanda | O35: INSIS, VTIME, INSUNIX | P35: Gaudy Sanchez | Q35: SÍ
A36: CRM | C36: =+UPPER(MID(B36,1,3))&"00"&COUNTA(B$3:B36) -> 004 | D36: Cliente | E36: Person | F36: Last_Name | G36: Apellido Paterno | H36: No acepta carácteres especiales, excepto: Apostrofe(') y Guiones (-). | I36: Básica | J36: NO | K36: Validez | L36: 1 | M36: 0.98 | N36: A demanda | O36: INSIS, VTIME, INSUNIX | P36: Gaudy Sanchez | Q36: SÍ
A37: CRM | C37: =+UPPER(MID(B37,1,3))&"00"&COUNTA(B$3:B37) -> 004 | D37: Cliente | E37: Person | F37: Last_Name | G37: Apellido Paterno | H37: No se acepta apellidos de menos de 2 carácteres. | I37: Básica | J37: NO | K37: Validez | L37: 1 | M37: 0.98 | N37: A demanda | O37: INSIS, VTIME, INSUNIX | P37: Gaudy Sanchez | Q37: SÍ
A38: CRM | C38: =+UPPER(MID(B38,1,3))&"00"&COUNTA(B$3:B38) -> 004 | D38: Cliente | E38: Person | F38: Last_Name | G38: Apellido Paterno | H38: No se acepta saltos de línea. | I38: Básica | J38: SÍ | K38: Validez | L38: 1 | M38: 0.98 | N38: A demanda | O38: INSIS, VTIME, INSUNIX | P38: Gaudy Sanchez | Q38: SÍ
A39: CRM | C39: =+UPPER(MID(B39,1,3))&"00"&COUNTA(B$3:B39) -> 004 | D39: Cliente | E39: Person | F39: Last_Name | G39: Apellido Paterno | H39: No se acepta tabulaciones. | I39: Básica | J39: NO | K39: Validez | L39: 1 | M39: 0.98 | N39: A demanda | O39: INSIS, VTIME, INSUNIX | P39: Gaudy Sanchez | Q39: SÍ
A40: CRM | C40: =+UPPER(MID(B40,1,3))&"00"&COUNTA(B$3:B40) -> 004 | D40: Cliente | E40: Person | F40: Last_Name | G40: Apellido Paterno | H40: Se aceptan apellidos compuestos. Ej: Suárez-Martínez o Del Río | I40: Experta | J40: SÍ | K40: Validez | L40: 1 | M40: 0.98 | N40: A demanda | O40: INSIS, VTIME, INSUNIX | P40: Gaudy Sanchez | Q40: SÍ
...

Sheet 3.Trazabilidad
A1: Iniciativa | B1: Caso de Uso | C1: Código de Entidad del Dato | D1: Tabla del Entidad de Dato (OMG) | E1: Campo del Entidad de Dato (OMG) | F1: Nombre de entidad del dato | G1: Llave | H1: Aplicativo(s) | I1: Fuente oficial | J1: Compañia | K1: Esquema | L1: Tabla en fuente oficial | M1: Campo en Fuente Oficial | N1: Personal | O1: Sensble | P1: Fuentes y campos necesarias para el cálculo o generación del dato | Q1: Ruta u Origen del Repositorio (Servidor) | R1: Data Entry (SI/NO) | S1: Periodicidad de Actualización | T1: Profundidad de datos | U1: Formato del Dato | V1: Longitud | W1: ¿Es llave primaria? | X1: Data Owner | Y1: Data Custodian | Z1: Validado por Data Custodian | AA1: Fecha de Actualización en el Diccionario Técnico | AB1: Actualización realizada en el Diccionario Técnico | AC1: Motivo de Actualización en el Diccionario Técnico | AD1: Responsable de la actualización en el Diccionario Técnico
A2: Iniciativa | B2: Caso de uso que corresponde | C2: Identificador único secuencial, asignado al Entidad de Dato por CDO | D2: Nombre de la entidad que se visualiza en la documentación de OMG | E2: Campo de la entidad que se visualiza en la documentación de OMG | F2: Nombre único con el cual el Negocio identifica al Entidad de Dato | H2: Nombre del aplicativo en el que se consulta/visualiza el dato | I2: Nombre del repositorio aprobado por el Dominio en donde se encuentra albergado este Dato | J2: Nompre de la compañía oficial de donde viene la tabla en fuente oficial. | K2: Agrupa las tablas dentro de la base de datos. | L2: Nombre de la tabla del aplicativo en el que se visualiza el Dato | M2: Nombre de campo desde donde se extrae el Concepto de Negocio por parte de la unidad de negocio | N2: Es dato personal si me permite identificar directamente a una persona natural. | O2: Tipificación de datos que requieren un tratamiento especial por su sinsibilidad. Ej: diagnóstico médico, N°tarjeta, sueldo del colaborador/cliente. | P2: Nombres de las fuentes y/o campos asociados a los datos calculados | Q2: Ruta física del repositorio, si es una dirección IP, Hostname en la que se encuentra | R2: Indicar SI, si el Dato es ingresado manualmente Indicar NO, si el Dato es obtenido por un proceso automático | S2: Indica la frecuencia requerida de actualización de la información, es decir la antigüedad máxima admitida del dato (e.g. si es suficiente con disponer de los datos del día anterior se indicaría D+1) | T2: Disponibilidad actual de datos históricos expresado en una unidad de tiempo (meses/fecha) | U2: Formato de dato de la Columna | V2: Número de caracteres o dígitos admitidos | W2: Indicador de si un campo es clave primaria de una tabla | X2: Nombre de la persona responsable de la gestión del dato. | Y2: Responsable de Tecnología | Z2: Una vez revisado por el Data Custodian colocar SÍ en señal de conformidad con la definición | AA2: Fecha en la que el dato fue actualizado | AB2: Descripción de la actualización realizada | AC2: Motivo de la actualización realizada | AD2: Nombre del colaborador que actualizó el dato
A3: CRM | B3: CRM | C3: =+UPPER(MID(B3,1,3))&"00"&COUNTA(B$3:B3) -> CRM001 | D3: Customer | E3: Party_Identifier | F3: Id Cliente | G3: =CONCATENATE(H3,".",J3,".",K3,".",L3,".",M3) -> INSIS.LPV.INSIS_PEOPLE_V10.P_CLIENTS.CLIENT_ID | H3: INSIS | I3: INSIS | J3: LPV | K3: INSIS_PEOPLE_V10 | L3: P_CLIENTS | M3: CLIENT_ID | N3: NO | O3: NO | P3: No aplica | Q3: 10.10.36.48 | R3: NO | S3: A demanda | T3: 2018 | U3: NUMERICO | V3: 10 | W3: SI | X3: Gaudy Sanchez | Y3: Javier Canchari | Z3: SÍ | AD3: Gobierno de Datos
A4: CRM | C4: =+UPPER(MID(B4,1,3))&"00"&COUNTA(B$3:B4) -> 001 | D4: Customer | E4: Party_Identifier | F4: Id Cliente | G4: =CONCATENATE(H4,".",J4,".",K4,".",L4,".",M4) -> VTIME.LPV.INSUDB.CLIENT.SCLIENT | H4: VTIME | I4: INSUDB | J4: LPV | K4: INSUDB | L4: CLIENT | M4: SCLIENT | N4: NO | O4: NO | P4: No aplica | Q4: PRD: 50.0.0.74 | R4: NO | S4: A demanda | T4: 2008 | U4: CHAR | V4: 14 | W4: SI | X4: Gaudy Sanchez | Y4: Fernando Fuentes | Z4: Si | AD4: Gobierno de Datos
A5: CRM | C5: =+UPPER(MID(B5,1,3))&"00"&COUNTA(B$3:B5) -> 001 | D5: Customer | E5: Party_Identifier | F5: Id Cliente | G5: =CONCATENATE(H5,".",J5,".",K5,".",L5,".",M5) -> VTIME.LPG.INSUDB.CLIENT.SCLIENT | H5: VTIME | I5: INSUDB | J5: LPG | K5: INSUDB | L5: CLIENT | M5: SCLIENT | N5: NO | O5: NO | P5: No aplica | Q5: 50.0.0.74 / oraprod | R5: NO | S5: A demanda | T5: 2008 | U5: CHAR | V5: 14 | W5: SI | X5: Gaudy Sanchez | Y5: Ellen Romero | Z5: Si | AD5: Gobierno de Datos
A6: CRM | C6: =+UPPER(MID(B6,1,3))&"00"&COUNTA(B$3:B6) -> 001 | D6: Customer | E6: Party_Identifier | F6: Id Cliente | G6: =CONCATENATE(H6,".",J6,".",K6,".",L6,".",M6) -> INSUNIX.LPV.INFORMIX.CLIENT.CODE | H6: INSUNIX | I6: INSUNIX | J6: LPV | K6: INFORMIX | L6: CLIENT | M6: CODE | N6: NO | O6: NO | P6: No aplica | Q6: 10.20.64.100 | R6: NO | S6: A demanda | T6: 1994 | U6: CHAR | V6: 11 | W6: SI | X6: Gaudy Sanchez | Y6: Javier Canchari | Z6: NO | AD6: Gobierno de Datos
A7: CRM | C7: =+UPPER(MID(B7,1,3))&"00"&COUNTA(B$3:B7) -> 001 | D7: Customer | E7: Party_Identifier | F7: Id Cliente | G7: =CONCATENATE(H7,".",J7,".",K7,".",L7,".",M7) -> INSUNIX.LPG.INFORMIX.CLIENT.CODE | H7: INSUNIX | I7: INSUNIX | J7: LPG | K7: INFORMIX | L7: CLIENT | M7: CODE | N7: NO | O7: NO | P7: No aplica | Q7: 10.20.162.27 | R7: NO | S7: A demanda | T7: 1994 | U7: CHAR | V7: 11 | W7: SI | X7: Gaudy Sanchez | Y7: Heli Rojas | Z7: Si | AD7: Gobierno de Datos
A8: CRM | C8: =+UPPER(MID(B8,1,3))&"00"&COUNTA(B$3:B8) -> 001 | D8: Customer | E8: Party_Identifier | F8: Id Cliente | G8: =CONCATENATE(H8,".",J8,".",K8,".",L8,".",M8) -> INSUNIX.LPE.INFORMIX.CLIENT.CODE | H8: INSUNIX | I8: INSUNIX | J8: LPE | K8: INFORMIX | L8: CLIENT | M8: CODE | P8: No aplica | Q8: 10.20.96.102 puerto: 1526 | R8: NO | S8: A demanda | T8: 1994 | U8: CHAR | V8: 11 | W8: SI | X8: Gaudy Sanchez | Y8: Cristian Torres | Z8: NO | AD8: Gobierno de Datos
A9: CRM | B9: CRM | C9: =+UPPER(MID(B9,1,3))&"00"&COUNTA(B$3:B9) -> CRM002 | D9: Person | E9: First_Name/Middle_Name | F9: Primer Nombre | G9: =CONCATENATE(H9,".",J9,".",K9,".",L9,".",M9) -> INSIS.LPV.INSIS_PEOPLE_V10.P_PEOPLE.GNAME | H9: INSIS | I9: INSIS | J9: LPV | K9: INSIS_PEOPLE_V10 | L9: P_PEOPLE | M9: GNAME | N9: SÍ | O9: NO | P9: No aplica | Q9: 10.10.36.48 | R9: NO | S9: A demanda | T9: 2018 | U9: VARCHAR2 | V9: 100 | W9: NO | X9: Gaudy Sanchez | Y9: Javier Canchari | Z9: SÍ | AD9: Gobierno de Datos
A10: CRM | C10: =+UPPER(MID(B10,1,3))&"00"&COUNTA(B$3:B10) -> 002 | D10: Person | E10: First_Name/Middle_Name | F10: Primer Nombre | G10: =CONCATENATE(H10,".",J10,".",K10,".",L10,".",M10) -> VTIME.LPV.INSUDB.CLIENT.SFIRSTNAME | H10: VTIME | I10: INSUDB | J10: LPV | K10: INSUDB | L10: CLIENT | M10: SFIRSTNAME | N10: SÍ | O10: NO | P10: No aplica | Q10: PRD: 50.0.0.74 | R10: NO | S10: A demanda | T10: 2008 | U10: VARCHAR2 | V10: 45 | W10: NO | X10: Gaudy Sanchez | Y10: Fernando Fuentes | Z10: Si | AD10: Gobierno de Datos
A11: CRM | C11: =+UPPER(MID(B11,1,3))&"00"&COUNTA(B$3:B11) -> 002 | D11: Person | E11: First_Name/Middle_Name | F11: Primer Nombre | G11: =CONCATENATE(H11,".",J11,".",K11,".",L11,".",M11) -> VTIME.LPG.INSUDB.CLIENT.SFIRSTNAME | H11: VTIME | I11: INSUDB | J11: LPG | K11: INSUDB | L11: CLIENT | M11: SFIRSTNAME | N11: SÍ | O11: NO | P11: No aplica | Q11: 50.0.0.74 / oraprod | R11: NO | S11: A demanda | T11: 2008 | U11: VARCHAR2 | V11: 45 | W11: NO | X11: Gaudy Sanchez | Y11: Ellen Romero | Z11: Si | AD11: Gobierno de Datos
A12: CRM | C12: =+UPPER(MID(B12,1,3))&"00"&COUNTA(B$3:B12) -> 002 | D12: Customer | E12: Party_Identifier | F12: Primer Nombre | G12: =CONCATENATE(H12,".",J12,".",K12,".",L12,".",M12) -> INSUNIX.LPV.INFORMIX.CLIENT.CLIENAME | H12: INSUNIX | I12: INSUNIX | J12: LPV | K12: INFORMIX | L12: CLIENT | M12: CLIENAME | N12: SÍ | O12: NO | P12: No aplica | Q12: 10.20.64.100 | R12: NO | S12: A demanda | T12: 1994 | U12: CHAR | V12: 40 | W12: NO | X12: Gaudy Sanchez | Y12: Javier Canchari | Z12: NO | AD12: Gobierno de Datos
A13: CRM | C13: =+UPPER(MID(B13,1,3))&"00"&COUNTA(B$3:B13) -> 002 | D13: Person | E13: First_Name/Middle_Name | F13: Primer Nombre | G13: =CONCATENATE(H13,".",J13,".",K13,".",L13,".",M13) -> INSUNIX.LPG.INFORMIX.CLIENT.CLIENAME | H13: INSUNIX | I13: INSUNIX | J13: LPG | K13: INFORMIX | L13: CLIENT | M13: CLIENAME | N13: SÍ | O13: NO | P13: No aplica | Q13: 10.20.162.27 | R13: NO | S13: A demanda | T13: 1994 | U13: CHAR | V13: 40 | W13: NO | X13: Gaudy Sanchez | Y13: Heli Rojas | Z13: Si | AD13: Gobierno de Datos
